<?xml version="1.0"?>
<robot xmlns:xacro="http://www.ros.org/wiki/xacro">

    <material name="red">
        <color rgba="1 0 0 1"/>
    </material>
    <material name="green">
        <color rgba="0 1 0 1"/>
    </material>
    <material name="blue">
        <color rgba="0 0 1 1"/>
    </material>
    <material name="yellow">
        <color rgba="1 1 0 1"/>
    </material>
     
     <!---base link -->

    <link name="base_link"/>
        
    <!--chassis link-->

    <joint name="chassis_joint" type="fixed">
        <parent link="base_link"/>
        <child link="chassis"/>
        <origin xyz="-0.1 0 0" rpy="0 0 0"/>
    </joint>
    <link name="chassis">
        <visual>
            <origin xyz="0.15 0 0.075" rpy="0 0 0"/>
            <geometry>
                <box size="0.35 0.25 0.15"/>
            </geometry>
            <material name="blue"/>
        </visual>
        <collision>
            <origin xyz="0.15 0 0.075" rpy="0 0 0"/>
            <geometry>
                <box size="0.35 0.25 0.15"/>
            </geometry>
        </collision>
        <inertial>
            <mass value="2.0"/>
            <origin xyz="0.15 0 0.075" rpy="0 0 0"/>
            <inertia ixx="0.01" ixy="0.0" ixz="0.0"
                     iyy="0.01" iyz="0.0"
                     izz="0.01"/>
        </inertial>
    </link>

    <!--left wheel link-->
    <joint name="left_wheel_joint" type="continuous">
        <parent link="chassis"/>
        <child link="left_wheel"/>
        <origin xyz="0.1 0.140 0" rpy="-${pi/2} 0 0"/>
        <axis xyz="0 0 1"/>
    </joint>
    <link name="left_wheel">
        <visual>
            <geometry>
                <cylinder radius="0.06" length="0.03"/>
            </geometry>
            <material name="red"/>
        </visual>
        <collision>
            <geometry>
                <cylinder radius="0.06" length="0.03"/>
            </geometry>
        </collision>
        <inertial>
            <mass value="0.2"/>
            <origin xyz="0 0 0" rpy="0 0 0"/>
            <inertia ixx="0.0001" ixy="0.0" ixz="0.0"
                     iyy="0.0001" iyz="0.0"
                     izz="0.0001"/>
        </inertial>
    </link>

    <!--right wheel link-->
    <joint name="right_wheel_joint" type="continuous">
        <parent link="chassis"/>
        <child link="right_wheel"/>
        <origin xyz="0.1 -0.140 0" rpy="${pi/2} 0 0"/>
        <axis xyz="0 0 -1"/>                                     
    </joint>
    <link name="right_wheel">
        <visual>
            <geometry>
                <cylinder radius="0.06" length="0.03"/>
            </geometry>
            <material name="green"/>
        </visual>
        <collision>
            <geometry>
                <cylinder radius="0.06" length="0.03"/>
            </geometry>
        </collision>
        <inertial>
            <mass value="0.2"/>
            <origin xyz="0 0 0" rpy="0 0 0"/>
            <inertia ixx="0.0001" ixy="0.0" ixz="0.0"
                     iyy="0.0001" iyz="0.0"
                     izz="0.0001"/>
        </inertial>
    </link>

    <!--caster link-->
    <joint name="left_caster_joint" type="fixed">
        <parent link="chassis"/>
        <child link="caster"/>
        <origin xyz="0.24 0 0"/>
    </joint>


    <link name="caster">
        <visual>
            <geometry>
                <sphere radius="0.04"/>
            </geometry>
            <material name="yellow"/>
        </visual>
        <collision>
            <geometry>
                <sphere radius="0.04"/>
            </geometry>
        </collision>
        <inertial>
            <mass value="0.05"/>
            <origin xyz="0 0 0" rpy="0 0 0"/>
            <inertia ixx="0.00001" ixy="0.0" ixz="0.0"
                     iyy="0.00001" iyz="0.0"
                     izz="0.00001"/>
        </inertial>
    </link>

    <gazebo reference="caster">
        <material>Gazebo/black</material>
        <mu1 value="0.001"/>
        <mu2 value="0.001"/>
    </gazebo>
    

</robot>